Workbook

Sheet Por Recursos Bajo
B1: Presupuesto de Proyecto Bajo | F1: RollerSpA
B2: Elaborado por: pmoinformatica.com | E2: % Reserva de Contingencia | G2: ='Presupuesto Detallado Bajo'!I2 -> 0.069665387
B3: Líder del Proyecto: Lucas Olea | E3: Presupuesto | F3: Reservas | G3: Total
B4: Fecha de Inicio: 18/08/2026 | D4: Total | E4: =G7+G26 -> 18230000 | F4: =E4*G2 -> 1270000 | G4: =SUM(E4:F4) -> 19500000
B6: Categoría | C6: Recurso | E6: Tipo de Unidades | F6: Tasa | G6: Presupuesto
B7: Costos Directos | G7: =G8+G14+G20+G22 -> 17450000
B8: Labor (Personal) | G8: =G9+G10+G11+G12+G13 -> 15600000
C9: Lucas Olea (Product Owner / Desarrollador) | E9: =VLOOKUP(C9,Datos!$B$8:$E$21,3,) -> Meses | F9: =VLOOKUP(C9,Datos!$B$8:$E$21,4,) -> 600000 | G9: =SUMIFS('Presupuesto Detallado Bajo'!$I$7:$I$39,'Presupuesto Detallado Bajo'!$D$7:$D$39,$C9) -> 3600000
C10: Rodrigo Soto (Arquitectura y UI-UX) | E10: =VLOOKUP(C10,Datos!$B$8:$E$21,3,) -> Meses | F10: =VLOOKUP(C10,Datos!$B$8:$E$21,4,) -> 600000 | G10: =SUMIFS('Presupuesto Detallado Bajo'!$I$7:$I$39,'Presupuesto Detallado Bajo'!$D$7:$D$39,$C10) -> 3600000
C11: Rodrigo Riquelme (QA Lead) | E11: =VLOOKUP(C11,Datos!$B$8:$E$21,3,) -> Meses | F11: =VLOOKUP(C11,Datos!$B$8:$E$21,4,) -> 600000 | G11: =SUMIFS('Presupuesto Detallado Bajo'!$I$7:$I$39,'Presupuesto Detallado Bajo'!$D$7:$D$39,$C11) -> 3600000
C12: Marco Robles (Scrum Master / Gestión de BD) | E12: =VLOOKUP(C12,Datos!$B$8:$E$21,3,) -> Meses | F12: =VLOOKUP(C12,Datos!$B$8:$E$21,4,) -> 500000 | G12: =SUMIFS('Presupuesto Detallado Bajo'!$I$7:$I$39,'Presupuesto Detallado Bajo'!$D$7:$D$39,$C12) -> 3000000
C13: Mantención y soporte (equipo de desarrollo) | E13: =VLOOKUP(C13,Datos!$B$8:$E$21,3,) -> Meses | F13: =VLOOKUP(C13,Datos!$B$8:$E$21,4,) -> 300000 | G13: =SUMIFS('Presupuesto Detallado Bajo'!$I$7:$I$39,'Presupuesto Detallado Bajo'!$D$7:$D$39,$C13) -> 1800000
B14: Materiales | G14: =G15+G16+G17+G18+G19 -> 1300000
C15: Equipamiento tecnológico complementario | E15: =VLOOKUP(C15,Datos!$B$8:$E$21,3,) -> Cantidad | F15: =VLOOKUP(C15,Datos!$B$8:$E$21,4,) -> 500000 | G15: =SUMIFS('Presupuesto Detallado Bajo'!$I$7:$I$39,'Presupuesto Detallado Bajo'!$D$7:$D$39,$C15) -> 500000
C16: Periféricos y accesorios | E16: =VLOOKUP(C16,Datos!$B$8:$E$21,3,) -> Cantidad | F16: =VLOOKUP(C16,Datos!$B$8:$E$21,4,) -> 250000 | G16: =SUMIFS('Presupuesto Detallado Bajo'!$I$7:$I$39,'Presupuesto Detallado Bajo'!$D$7:$D$39,$C16) -> 250000
C17: Respaldo y almacenamiento externo | E17: =VLOOKUP(C17,Datos!$B$8:$E$21,3,) -> Cantidad | F17: =VLOOKUP(C17,Datos!$B$8:$E$21,4,) -> 150000 | G17: =SUMIFS('Presupuesto Detallado Bajo'!$I$7:$I$39,'Presupuesto Detallado Bajo'!$D$7:$D$39,$C17) -> 150000
C18: Dispositivos de prueba móviles | E18: =VLOOKUP(C18,Datos!$B$8:$E$21,3,) -> Cantidad | F18: =VLOOKUP(C18,Datos!$B$8:$E$21,4,) -> 250000 | G18: =SUMIFS('Presupuesto Detallado Bajo'!$I$7:$I$39,'Presupuesto Detallado Bajo'!$D$7:$D$39,$C18) -> 250000
C19: Diseño y recursos gráficos | E19: =VLOOKUP(C19,Datos!$B$8:$E$21,3,) -> Cantidad | F19: =VLOOKUP(C19,Datos!$B$8:$E$21,4,) -> 150000 | G19: =SUMIFS('Presupuesto Detallado Bajo'!$I$7:$I$39,'Presupuesto Detallado Bajo'!$D$7:$D$39,$C19) -> 150000
B20: Licencias | G20: =G21 -> 150000
C21: Licencias y herramientas de desarrollo | E21: =VLOOKUP(C21,Datos!$B$8:$E$21,3,) -> Cantidad | F21: =VLOOKUP(C21,Datos!$B$8:$E$21,4,) -> 150000 | G21: =SUMIFS('Presupuesto Detallado Bajo'!$I$7:$I$39,'Presupuesto Detallado Bajo'!$D$7:$D$39,$C21) -> 150000
B22: Servicios Técnicos | G22: =G23+G24+G25 -> 400000
C23: Configuración inicial del entorno / Cloud | E23: =VLOOKUP(C23,Datos!$B$8:$G$29,3,FALSE()) -> Cantidad | F23: =VLOOKUP(C23,Datos!$B$8:$G$29,4,FALSE()) -> 100000 | G23: =SUMIFS('Presupuesto Detallado Bajo'!$I$7:$I$39,'Presupuesto Detallado Bajo'!$D$7:$D$39,$C23) -> 100000
C24: Cloud y despliegue | E24: =VLOOKUP(C24,Datos!$B$8:$G$29,3,FALSE()) -> Cantidad | F24: =VLOOKUP(C24,Datos!$B$8:$G$29,4,FALSE()) -> 200000 | G24: =SUMIFS('Presupuesto Detallado Bajo'!$I$7:$I$39,'Presupuesto Detallado Bajo'!$D$7:$D$39,$C24) -> 200000
C25: Documentación y entrega | E25: =VLOOKUP(C25,Datos!$B$8:$G$29,3,FALSE()) -> Cantidad | F25: =VLOOKUP(C25,Datos!$B$8:$G$29,4,FALSE()) -> 100000 | G25: =SUMIFS('Presupuesto Detallado Bajo'!$I$7:$I$39,'Presupuesto Detallado Bajo'!$D$7:$D$39,$C25) -> 100000
B26: Costos Indirectos | G26: =G27+G28 -> 780000
C27: Servicios básicos / Internet | E27: =VLOOKUP(C27,Datos!$B$8:$G$29,3,FALSE()) -> Meses | F27: =VLOOKUP(C27,Datos!$B$8:$G$29,4,FALSE()) -> 100000 | G27: =SUMIFS('Presupuesto Detallado Bajo'!$I$7:$I$39,'Presupuesto Detallado Bajo'!$D$7:$D$39,$C27) -> 600000
C28: Dominio, correo y servicios digitales | E28: =VLOOKUP(C28,Datos!$B$8:$G$29,3,FALSE()) -> Meses | F28: =VLOOKUP(C28,Datos!$B$8:$G$29,4,FALSE()) -> 30000 | G28: =SUMIFS('Presupuesto Detallado Bajo'!$I$7:$I$39,'Presupuesto Detallado Bajo'!$D$7:$D$39,$C28) -> 180000
B31: Conciliación con el flujo de caja
C32: Concepto | D32: Flujo de caja | E32: Presupuesto | F32: Diferencia
C33: Costos de personal 6 meses | D33: =(F9+F10+F11+F12+F13)*6 -> 15600000 | E33: ='Presupuesto Detallado Bajo'!I20+'Presupuesto Detallado Bajo'!I34 -> 15600000 | F33: =E33-D33 -> 0
C34: Gastos operacionales | D34: =(F27+F28)*6 -> 780000 | E34: ='Presupuesto Detallado Bajo'!I36 -> 780000 | F34: =E34-D34 -> 0
C35: Costos tecnológicos | D35: 1350000 | E35: ='Presupuesto Detallado Bajo'!I13+'Presupuesto Detallado Bajo'!I25 -> 1350000 | F35: =E35-D35 -> 0
C36: Inversión inicial | D36: 500000 | E36: ='Presupuesto Detallado Bajo'!I8 -> 500000 | F36: =E36-D36 -> 0
C37: Margen de seguridad / contingencia | D37: 1270000 | E37: ='Presupuesto Detallado Bajo'!H4 -> 1270000 | F37: =E37-D37 -> 0
C38: Costo total estimado | D38: =D33+D34+D35+D36+D37 -> 19500000

Sheet Presupuesto Detallado Bajo
B1: Presupuesto de Proyecto Bajo | G1: RollerSpA
B2: Elaborado por: pmoinformatica.com | G2: % Reserva de Contingencia | I2: =IF(G4=0,0,'Por Recursos Bajo'!D37/G4) -> 0.069665387
B3: Líder del Proyecto: Lucas Olea | G3: Presupuesto | H3: Reservas | I3: Total
B4: Fecha de Inicio: 18/08/2026 | E4: Total | G4: =I7+I18+I32 -> 18230000 | H4: =G4*I2 -> 1270000 | I4: =SUM(G4:H4) -> 19500000
B6: Código | C6: Tarea / Actividad | D6: Elemento | E6: Tipo de Recurso | F6: Tipo de Unidades | G6: Unidades | H6: Tasa | I6: Presupuesto
B7: 1 | C7: Inversión inicial y arranque (Mes 0 - M2) | I7: =I8+I13 -> 1300000
B8: 1.1 | C8: Inversión inicial (Mes 0) | I8: =I9 -> 500000
B9: 1.1.1 | C9: Equipamiento y configuración inicial | I9: =SUM(I10:I12) -> 500000
D10: Periféricos y accesorios | E10: =VLOOKUP(D10,Datos!$B$8:$E$21,2,) -> Materiales | F10: =VLOOKUP(D10,Datos!$B$8:$E$21,3,) -> Cantidad | G10: 1 | H10: =VLOOKUP(D10,Datos!$B$8:$E$21,4,) -> 250000 | I10: =G10*H10 -> 250000
D11: Respaldo y almacenamiento externo | E11: =VLOOKUP(D11,Datos!$B$8:$E$21,2,) -> Materiales | F11: =VLOOKUP(D11,Datos!$B$8:$E$21,3,) -> Cantidad | G11: 1 | H11: =VLOOKUP(D11,Datos!$B$8:$E$21,4) -> 150000 | I11: =G11*H11 -> 150000
D12: Configuración inicial del entorno / Cloud | E12: =VLOOKUP(D12,Datos!$B$8:$G$29,2,FALSE()) -> Servicios Técnicos | F12: =VLOOKUP(D12,Datos!$B$8:$G$29,3,FALSE()) -> Cantidad | G12: 1 | H12: =VLOOKUP(D12,Datos!$B$8:$G$29,4,FALSE()) -> 100000 | I12: =G12*H12 -> 100000
B13: 46054 | C13: Herramientas y recursos de diseño (M1 - M2) | I13: =I14 -> 800000
B14: 1.2.1 | C14: Licencias, equipamiento complementario y diseño | I14: =I15+I16+I17 -> 800000
D15: Equipamiento tecnológico complementario | E15: =VLOOKUP(D15,Datos!$B$8:$E$21,2,) -> Materiales | F15: =VLOOKUP(D15,Datos!$B$8:$E$21,3,) -> Cantidad | G15: 1 | H15: =VLOOKUP(D15,Datos!$B$8:$G$29,4,FALSE()) -> 500000 | I15: =G15*H15 -> 500000
D16: Licencias y herramientas de desarrollo | E16: =VLOOKUP(D16,Datos!$B$8:$E$21,2,) -> Licencias | F16: =VLOOKUP(D16,Datos!$B$8:$E$21,3,) -> Cantidad | G16: 1 | H16: =VLOOKUP(D16,Datos!$B$8:$G$29,4,FALSE()) -> 150000 | I16: =G16*H16 -> 150000
D17: Diseño y recursos gráficos | E17: =VLOOKUP(D17,Datos!$B$8:$E$21,2,) -> Materiales | F17: =VLOOKUP(D17,Datos!$B$8:$E$21,3,) -> Cantidad | G17: 1 | H17: =VLOOKUP(D17,Datos!$B$8:$G$29,4,FALSE()) -> 150000 | I17: =G17*H17 -> 150000
B18: 2 | C18: Desarrollo, pruebas y entrega (M1 - M6) | I18: =I19+I25 -> 14350000
B19: 2.1 | C19: Desarrollo del sistema | I19: =I20 -> 13800000
B20: 2.1.1 | C20: Equipo de desarrollo (M1-M6) | I20: =SUM(I21:I24) -> 13800000
D21: Lucas Olea (Product Owner / Desarrollador) | E21: =VLOOKUP(D21,Datos!$B$8:$E$21,2,) -> Labor (Personal) | F21: =VLOOKUP(D21,Datos!$B$8:$E$21,3,) -> Meses | G21: 6 | H21: =VLOOKUP(D21,Datos!$B$8:$E$21,4,) -> 600000 | I21: =G21*H21 -> 3600000
D22: Rodrigo Soto (Arquitectura y UI-UX) | E22: =VLOOKUP(D22,Datos!$B$8:$E$21,2,) -> Labor (Personal) | F22: =VLOOKUP(D22,Datos!$B$8:$E$21,3,) -> Meses | G22: 6 | H22: =VLOOKUP(D22,Datos!$B$8:$G$29,4,FALSE()) -> 600000 | I22: =G22*H22 -> 3600000
D23: Rodrigo Riquelme (QA Lead) | E23: =VLOOKUP(D23,Datos!$B$8:$E$21,2,) -> Labor (Personal) | F23: =VLOOKUP(D23,Datos!$B$8:$E$21,3,) -> Meses | G23: 6 | H23: =VLOOKUP(D23,Datos!$B$8:$G$29,4,FALSE()) -> 600000 | I23: =G23*H23 -> 3600000
D24: Marco Robles (Scrum Master / Gestión de BD) | E24: =VLOOKUP(D24,Datos!$B$8:$E$21,2,) -> Labor (Personal) | F24: =VLOOKUP(D24,Datos!$B$8:$E$21,3,) -> Meses | G24: 6 | H24: =VLOOKUP(D24,Datos!$B$8:$E$21,4) -> 500000 | I24: =G24*H24 -> 3000000
B25: 46055 | C25: Pruebas, despliegue y entrega | I25: =I26+I28+I30 -> 550000
B26: 2.2.1 | C26: Pruebas y QA (M2-M3) | I26: =I27 -> 250000
D27: Dispositivos de prueba móviles | E27: =VLOOKUP(D27,Datos!$B$8:$E$21,2,) -> Materiales | F27: =VLOOKUP(D27,Datos!$B$8:$E$21,3,) -> Cantidad | G27: 1 | H27: =VLOOKUP(D27,Datos!$B$8:$E$21,4,) -> 250000 | I27: =G27*H27 -> 250000
B28: 2.2.2 | C28: Cloud y despliegue (M5) | I28: =I29 -> 200000
D29: Cloud y despliegue | E29: =VLOOKUP(D29,Datos!$B$8:$G$29,2,FALSE()) -> Servicios Técnicos | F29: =VLOOKUP(D29,Datos!$B$8:$G$29,3,FALSE()) -> Cantidad | G29: 1 | H29: =VLOOKUP(D29,Datos!$B$8:$G$29,4,FALSE()) -> 200000 | I29: =G29*H29 -> 200000
B30: 2.2.3 | C30: Documentación y entrega (M6) | I30: =I31 -> 100000
D31: Documentación y entrega | E31: =VLOOKUP(D31,Datos!$B$8:$G$29,2,FALSE()) -> Servicios Técnicos | F31: =VLOOKUP(D31,Datos!$B$8:$G$29,3,FALSE()) -> Cantidad | G31: 1 | H31: =VLOOKUP(D31,Datos!$B$8:$G$29,4,FALSE()) -> 100000 | I31: =G31*H31 -> 100000
B32: 3 | C32: Desarrollo, pruebas y entrega (M1 - M6) | I32: =I33+I36 -> 2580000
B33: 46025 | C33: Soporte y mantención | I33: =I34 -> 1800000
B34: 3.1.1 | C34: Mantención y soporte (M1-M6) | I34: =SUM(I35) -> 1800000
D35: Mantención y soporte (equipo de desarrollo) | E35: =VLOOKUP(D35,Datos!$B$8:$E$21,2,) -> Labor (Personal) | F35: =VLOOKUP(D35,Datos!$B$8:$E$21,3,) -> Meses | G35: 6 | H35: =VLOOKUP(D35,Datos!$B$8:$E$21,4,) -> 300000 | I35: =G35*H35 -> 1800000
B36: 46056 | C36: Gastos operacionales | I36: =I37 -> 780000
B37: 3.2.1 | C37: Servicios y gastos generales (M1 - M6) | I37: =+I38+I39 -> 780000
D38: Servicios básicos / Internet | E38: =VLOOKUP(D38,Datos!$B$8:$G$29,2,FALSE()) -> Gastos Indirectos | F38: =VLOOKUP(D38,Datos!$B$8:$G$29,3,FALSE()) -> Meses | G38: 6 | H38: =VLOOKUP(D38,Datos!$B$8:$G$29,4,FALSE()) -> 100000 | I38: =H38*G38 -> 600000
D39: Dominio, correo y servicios digitales | E39: =VLOOKUP(D39,Datos!$B$8:$G$29,2,FALSE()) -> Gastos Indirectos | F39: =VLOOKUP(D39,Datos!$B$8:$G$29,3,FALSE()) -> Meses | G39: 6 | H39: =VLOOKUP(D39,Datos!$B$8:$G$29,4,FALSE()) -> 30000 | I39: =H39*G39 -> 180000

Sheet Por Recursos Medio
B1: Presupuesto de Proyecto Medio | F1: RollerSpA
B2: Elaborado por: pmoinformatica.com | E2: % Reserva de Contingencia | G2: ='Presupuesto Detallado Medio'!I2 -> 0.056587091
B3: Líder del Proyecto: Lucas Olea | E3: Presupuesto | F3: Reservas | G3: Total
B4: Fecha de Inicio: 18/08/2026 | D4: Total | E4: =G7+G27 -> 22620000 | F4: =E4*G2 -> 1280000 | G4: =SUM(E4:F4) -> 23900000
B6: Categoría | C6: Recurso | E6: Tipo de Unidades | F6: Tasa | G6: Presupuesto
B7: Costos Directos | G7: =G8+G14+G21+G23 -> 21600000
B8: Labor (Personal) | G8: =G9+G10+G11+G12+G13 -> 19200000
C9: Lucas Olea (Product Owner / Desarrollador) | E9: =VLOOKUP(C9,Datos!$B$8:$E$21,3,) -> Meses | F9: =VLOOKUP(C9,Datos!$B$8:$G$29,5,FALSE()) -> 700000 | G9: =SUMIFS('Presupuesto Detallado Medio'!$I$7:$I$39,'Presupuesto Detallado Medio'!$D$7:$D$39,$C9) -> 4200000
C10: Rodrigo Soto (Arquitectura y UI-UX) | E10: =VLOOKUP(C10,Datos!$B$8:$E$21,3,) -> Meses | F10: =VLOOKUP(C10,Datos!$B$8:$G$29,5,FALSE()) -> 750000 | G10: =SUMIFS('Presupuesto Detallado Medio'!$I$7:$I$39,'Presupuesto Detallado Medio'!$D$7:$D$39,$C10) -> 4500000
C11: Rodrigo Riquelme (QA Lead) | E11: =VLOOKUP(C11,Datos!$B$8:$E$21,3,) -> Meses | F11: =VLOOKUP(C11,Datos!$B$8:$G$29,5,FALSE()) -> 750000 | G11: =SUMIFS('Presupuesto Detallado Medio'!$I$7:$I$39,'Presupuesto Detallado Medio'!$D$7:$D$39,$C11) -> 4500000
C12: Marco Robles (Scrum Master / Gestión de BD) | E12: =VLOOKUP(C12,Datos!$B$8:$E$21,3,) -> Meses | F12: =VLOOKUP(C12,Datos!$B$8:$G$29,5,FALSE()) -> 650000 | G12: =SUMIFS('Presupuesto Detallado Medio'!$I$7:$I$39,'Presupuesto Detallado Medio'!$D$7:$D$39,$C12) -> 3900000
C13: Mantención y soporte (equipo de desarrollo) | E13: =VLOOKUP(C13,Datos!$B$8:$E$21,3,) -> Meses | F13: =VLOOKUP(C13,Datos!$B$8:$G$29,5,FALSE()) -> 350000 | G13: =SUMIFS('Presupuesto Detallado Medio'!$I$7:$I$39,'Presupuesto Detallado Medio'!$D$7:$D$39,$C13) -> 2100000
B14: Materiales | G14: =G15+G16+G17+G18+G19+G20 -> 1600000
C15: Equipamiento tecnológico | E15: =VLOOKUP(C15,Datos!$B$8:$E$21,3,) -> Cantidad | F15: =VLOOKUP(C15,Datos!$B$8:$G$29,5,FALSE()) -> 500000 | G15: =SUMIFS('Presupuesto Detallado Medio'!$I$7:$I$40,'Presupuesto Detallado Medio'!$D$7:$D$40,$C15) -> 500000
C16: Periféricos y accesorios | E16: =VLOOKUP(C16,Datos!$B$8:$E$21,3,) -> Cantidad | F16: =VLOOKUP(C16,Datos!$B$8:$G$29,5,FALSE()) -> 200000 | G16: =SUMIFS('Presupuesto Detallado Medio'!$I$7:$I$40,'Presupuesto Detallado Medio'!$D$7:$D$40,$C16) -> 200000
C17: Respaldo y almacenamiento externo | E17: =VLOOKUP(C17,Datos!$B$8:$E$21,3,) -> Cantidad | F17: =VLOOKUP(C17,Datos!$B$8:$G$29,5,FALSE()) -> 150000 | G17: =SUMIFS('Presupuesto Detallado Medio'!$I$7:$I$40,'Presupuesto Detallado Medio'!$D$7:$D$40,$C17) -> 150000
C18: Dispositivos de prueba móviles | E18: =VLOOKUP(C18,Datos!$B$8:$E$21,3,) -> Cantidad | F18: =VLOOKUP(C18,Datos!$B$8:$G$29,5,FALSE()) -> 300000 | G18: =SUMIFS('Presupuesto Detallado Medio'!$I$7:$I$40,'Presupuesto Detallado Medio'!$D$7:$D$40,$C18) -> 300000
C19: Diseño y recursos gráficos | E19: =VLOOKUP(C19,Datos!$B$8:$E$21,3,) -> Cantidad | F19: =VLOOKUP(C19,Datos!$B$8:$G$29,5,FALSE()) -> 200000 | G19: =SUMIFS('Presupuesto Detallado Medio'!$I$7:$I$40,'Presupuesto Detallado Medio'!$D$7:$D$40,$C19) -> 200000
C20: Materiales QA | E20: =VLOOKUP(C20,Datos!$B$8:$E$21,3,) -> Cantidad | F20: =VLOOKUP(C20,Datos!$B$8:$G$29,5,FALSE()) -> 250000 | G20: =SUMIFS('Presupuesto Detallado Medio'!$I$7:$I$40,'Presupuesto Detallado Medio'!$D$7:$D$40,$C20) -> 250000
B21: Licencias | G21: =G22 -> 200000
C22: Licencias y herramientas de desarrollo | E22: =VLOOKUP(C22,Datos!$B$8:$E$21,3,) -> Cantidad | F22: =VLOOKUP(C22,Datos!$B$8:$G$29,5,FALSE()) -> 200000 | G22: =SUMIFS('Presupuesto Detallado Medio'!$I$7:$I$40,'Presupuesto Detallado Medio'!$D$7:$D$40,$C22) -> 200000
B23: Servicios Técnicos | G23: =G24+G25+G26 -> 600000
C24: Configuración inicial del entorno / Cloud | E24: =VLOOKUP(C24,Datos!$B$8:$G$29,3,FALSE()) -> Cantidad | F24: =VLOOKUP(C24,Datos!$B$8:$G$29,5,FALSE()) -> 150000 | G24: =SUMIFS('Presupuesto Detallado Medio'!$I$7:$I$40,'Presupuesto Detallado Medio'!$D$7:$D$40,$C24) -> 150000
C25: Cloud y despliegue | E25: =VLOOKUP(C25,Datos!$B$8:$G$29,3,FALSE()) -> Cantidad | F25: =VLOOKUP(C25,Datos!$B$8:$G$29,5,FALSE()) -> 300000 | G25: =SUMIFS('Presupuesto Detallado Medio'!$I$7:$I$40,'Presupuesto Detallado Medio'!$D$7:$D$40,$C25) -> 300000
C26: Documentación y entrega | E26: =VLOOKUP(C26,Datos!$B$8:$G$29,3,FALSE()) -> Cantidad | F26: =VLOOKUP(C26,Datos!$B$8:$G$29,5,FALSE()) -> 150000 | G26: =SUMIFS('Presupuesto Detallado Medio'!$I$7:$I$40,'Presupuesto Detallado Medio'!$D$7:$D$40,$C26) -> 150000
B27: Costos Indirectos | G27: =G28+G29 -> 1020000
C28: Servicios básicos / Internet | E28: =VLOOKUP(C28,Datos!$B$8:$G$29,3,FALSE()) -> Meses | F28: =VLOOKUP(C28,Datos!$B$8:$G$29,5,FALSE()) -> 120000 | G28: =SUMIFS('Presupuesto Detallado Medio'!$I$7:$I$40,'Presupuesto Detallado Medio'!$D$7:$D$40,$C28) -> 720000
C29: Dominio, correo y servicios digitales | E29: =VLOOKUP(C29,Datos!$B$8:$G$29,3,FALSE()) -> Meses | F29: =VLOOKUP(C29,Datos!$B$8:$G$29,5,FALSE()) -> 50000 | G29: =SUMIFS('Presupuesto Detallado Medio'!$I$7:$I$40,'Presupuesto Detallado Medio'!$D$7:$D$40,$C29) -> 300000
B32: Conciliación con el flujo de caja
C33: Concepto | D33: Flujo de caja | E33: Presupuesto | F33: Diferencia
C34: Costos de personal 6 meses | D34: =(F9+F10+F11+F12+F13)*6 -> 19200000 | E34: ='Presupuesto Detallado Medio'!I20+'Presupuesto Detallado Medio'!I34 -> 19200000 | F34: =E34-D34 -> 0
C35: Gastos operacionales | D35: 3120000 | E35: ='Presupuesto Detallado Medio'!I38 -> 1020000 | F35: =E35-D35 -> -2100000
C36: Costos tecnológicos | D36: 1400000 | E36: ='Presupuesto Detallado Medio'!I14+'Presupuesto Detallado Medio'!I25 -> 1400000 | F36: =E36-D36 -> 0
C37: Inversión inicial | D37: 1000000 | E37: ='Presupuesto Detallado Medio'!I8 -> 1000000 | F37: =E37-D37 -> 0
C38: Margen de seguridad / contingencia | D38: 1280000 | E38: ='Presupuesto Detallado Medio'!H4 -> 1280000 | F38: =E38-D38 -> 0
C39: Costo total estimado | D39: =D34+D35+D36+D37+D38 -> 26000000 | E39: =SUM(E34:E38) -> 23900000 | F39: =SUM(F34:F38) -> -2100000

Sheet Presupuesto Detallado Medio
B1: Presupuesto de Proyecto Medio | G1: RollerSpA
B2: Elaborado por: pmoinformatica.com | G2: % Reserva de Contingencia | I2: =IF(G4=0,0,'Por Recursos Medio'!D38/G4) -> 0.056587091
B3: Líder del Proyecto: Lucas Olea | G3: Presupuesto | H3: Reservas | I3: Total
B4: Fecha de Inicio: 18/08/2026 | E4: Total | G4: =I7+I18+I33 -> 22620000 | H4: =G4*I2 -> 1280000 | I4: =SUM(G4:H4) -> 23900000
B6: Código | C6: Tarea / Actividad | D6: Elemento | E6: Tipo de Recurso | F6: Tipo de Unidades | G6: Unidades | H6: Tasa | I6: Presupuesto
B7: 1 | C7: Inversión inicial y arranque (Mes 0 - M2) | I7: =I8+I14 -> 1400000
B8: 1.1 | C8: Inversión inicial (Mes 0) | I8: =I9 -> 1000000
B9: 1.1.1 | C9: Equipamiento y configuración inicial | H9: =VLOOKUP(D10,Datos!$B$8:$E$21,4,) | I9: =SUM(I10:I13) -> 1000000
D10: Equipamiento tecnológico | E10: =VLOOKUP(D10,Datos!$B$8:$E$21,2,) -> Materiales | F10: =VLOOKUP(D10,Datos!$B$8:$E$21,3,) -> Cantidad | G10: 1 | H10: =VLOOKUP(D10,Datos!$B$8:$G$29,5,FALSE()) -> 500000 | I10: =H10*G10 -> 500000
D11: Periféricos y accesorios | E11: =VLOOKUP(D11,Datos!$B$8:$E$21,2,) -> Materiales | F11: =VLOOKUP(D11,Datos!$B$8:$E$21,3,) -> Cantidad | G11: 1 | H11: =VLOOKUP(D11,Datos!$B$8:$G$29,5,FALSE()) -> 200000 | I11: =H11*G11 -> 200000
D12: Respaldo y almacenamiento externo | E12: =VLOOKUP(D12,Datos!$B$8:$G$29,2,FALSE()) -> Materiales | F12: =VLOOKUP(D12,Datos!$B$8:$G$29,3,FALSE()) -> Cantidad | G12: 1 | H12: =VLOOKUP(D12,Datos!$B$8:$G$29,5,FALSE()) -> 150000 | I12: =H12*G12 -> 150000
D13: Configuración inicial del entorno / Cloud | E13: =VLOOKUP(D13,Datos!$B$8:$G$29,2,FALSE()) -> Servicios Técnicos | F13: =VLOOKUP(D12,Datos!$B$8:$G$29,3,FALSE()) -> Cantidad | G13: 1 | H13: =VLOOKUP(D13,Datos!$B$8:$G$29,5,FALSE()) -> 150000 | I13: =H13*G13 -> 150000
B14: 46054 | C14: Herramientas y recursos de diseño (M1 - M2) | I14: =I15 -> 400000
B15: 1.2.1 | C15: Licencias, equipamiento complementario y diseño | I15: =I16+I17 -> 400000
D16: Licencias y herramientas de desarrollo | E16: =VLOOKUP(D16,Datos!$B$8:$E$21,2,) -> Licencias | F16: =VLOOKUP(D16,Datos!$B$8:$E$21,3,) -> Cantidad | G16: 1 | H16: =VLOOKUP(D16,Datos!$B$8:$G$29,5,FALSE()) -> 200000 | I16: =G16*H16 -> 200000
D17: Diseño y recursos gráficos | E17: =VLOOKUP(D17,Datos!$B$8:$E$21,2,) -> Materiales | F17: =VLOOKUP(D17,Datos!$B$8:$E$21,3,) -> Cantidad | G17: 1 | H17: =VLOOKUP(D16,Datos!$B$8:$G$29,5,FALSE()) -> 200000 | I17: =G17*H17 -> 200000
B18: 2 | C18: Desarrollo, pruebas y entrega (M1 - M6) | I18: =I19+I25 -> 18100000
B19: 2.1 | C19: Desarrollo del sistema | I19: =I20 -> 17100000
B20: 2.1.1 | C20: Equipo de desarrollo (M1-M6) | I20: =SUM(I21:I24) -> 17100000
D21: Lucas Olea (Product Owner / Desarrollador) | E21: =VLOOKUP(D21,Datos!$B$8:$E$21,2,) -> Labor (Personal) | F21: =VLOOKUP(D21,Datos!$B$8:$E$21,3,) -> Meses | G21: 6 | H21: =VLOOKUP(D21,Datos!$B$8:$G$29,5,FALSE()) -> 700000 | I21: =G21*H21 -> 4200000
D22: Rodrigo Soto (Arquitectura y UI-UX) | E22: =VLOOKUP(D22,Datos!$B$8:$E$21,2,) -> Labor (Personal) | F22: =VLOOKUP(D22,Datos!$B$8:$E$21,3,) -> Meses | G22: 6 | H22: =VLOOKUP(D22,Datos!$B$8:$G$29,5,FALSE()) -> 750000 | I22: =G22*H22 -> 4500000
D23: Rodrigo Riquelme (QA Lead) | E23: =VLOOKUP(D23,Datos!$B$8:$E$21,2,) -> Labor (Personal) | F23: =VLOOKUP(D23,Datos!$B$8:$E$21,3,) -> Meses | G23: 6 | H23: =VLOOKUP(D23,Datos!$B$8:$G$29,5,FALSE()) -> 750000 | I23: =G23*H23 -> 4500000
D24: Marco Robles (Scrum Master / Gestión de BD) | E24: =VLOOKUP(D24,Datos!$B$8:$E$21,2,) -> Labor (Personal) | F24: =VLOOKUP(D24,Datos!$B$8:$E$21,3,) -> Meses | G24: 6 | H24: =VLOOKUP(D24,Datos!$B$8:$G$29,5,FALSE()) -> 650000 | I24: =G24*H24 -> 3900000
B25: 46055 | C25: Pruebas, despliegue y entrega | I25: =I26+I29+I31 -> 1000000
B26: 2.2.1 | C26: Pruebas y QA (M2-M3) | I26: =I27+I28 -> 550000
D27: Dispositivos de prueba móviles | E27: =VLOOKUP(D27,Datos!$B$8:$E$21,2,) -> Materiales | F27: =VLOOKUP(D27,Datos!$B$8:$E$21,3,) -> Cantidad | G27: 1 | H27: =VLOOKUP(D27,Datos!$B$8:$G$29,5,FALSE()) -> 300000 | I27: =G27*H27 -> 300000
D28: Materiales QA | E28: =VLOOKUP(D28,Datos!$B$8:$E$21,2,) -> Materiales | F28: =VLOOKUP(D28,Datos!$B$8:$E$21,3,) -> Cantidad | G28: 1 | H28: =VLOOKUP(D28,Datos!$B$8:$G$29,5,FALSE()) -> 250000 | I28: =H28*G28 -> 250000
B29: 2.2.2 | C29: Cloud y despliegue (M5) | I29: =I30 -> 300000
D30: Cloud y despliegue | E30: =VLOOKUP(D30,Datos!$B$8:$G$29,2,FALSE()) -> Servicios Técnicos | F30: =VLOOKUP(D30,Datos!$B$8:$G$29,3,FALSE()) -> Cantidad | G30: 1 | H30: =VLOOKUP(D30,Datos!$B$8:$G$29,5,FALSE()) -> 300000 | I30: =G30*H30 -> 300000
B31: 2.2.3 | C31: Documentación y entrega (M6) | I31: =I32 -> 150000
D32: Documentación y entrega | E32: =VLOOKUP(D32,Datos!$B$8:$G$29,2,FALSE()) -> Servicios Técnicos | F32: =VLOOKUP(D32,Datos!$B$8:$G$29,3,FALSE()) -> Cantidad | G32: 1 | H32: =VLOOKUP(D32,Datos!$B$8:$G$29,5,FALSE()) -> 150000 | I32: =G32*H32 -> 150000
B33: 3 | C33: Desarrollo, pruebas y entrega (M1 - M6) | I33: =I34+I37 -> 3120000
B34: 46025 | C34: Soporte y mantención | I34: =I35 -> 2100000
B35: 3.1.1 | C35: Mantención y soporte (M1-M6) | I35: =SUM(I36) -> 2100000
D36: Mantención y soporte (equipo de desarrollo) | E36: =VLOOKUP(D36,Datos!$B$8:$E$21,2,) -> Labor (Personal) | F36: =VLOOKUP(D36,Datos!$B$8:$E$21,3,) -> Meses | G36: 6 | H36: =VLOOKUP(D36,Datos!$B$8:$G$29,5,FALSE()) -> 350000 | I36: =G36*H36 -> 2100000
B37: 46056 | C37: Gastos operacionales | I37: =I38 -> 1020000
B38: 3.2.1 | C38: Servicios y gastos generales (M1 - M6) | I38: =+I39+I40 -> 1020000
D39: Servicios básicos / Internet | E39: =VLOOKUP(D39,Datos!$B$8:$G$29,2,FALSE()) -> Gastos Indirectos | F39: =VLOOKUP(D39,Datos!$B$8:$G$29,3,FALSE()) -> Meses | G39: 6 | H39: =VLOOKUP(D39,Datos!$B$8:$G$29,5,FALSE()) -> 120000 | I39: =H39*G39 -> 720000
D40: Dominio, correo y servicios digitales | E40: =VLOOKUP(D40,Datos!$B$8:$G$29,2,FALSE()) -> Gastos Indirectos | F40: =VLOOKUP(D40,Datos!$B$8:$G$29,3,FALSE()) -> Meses | G40: 6 | H40: =VLOOKUP(D40,Datos!$B$8:$G$29,5,FALSE()) -> 50000 | I40: =H40*G40 -> 300000

Sheet Por Recursos Alto
B1: Presupuesto de Proyecto Alto | F1: RollerSpA
B2: Elaborado por: pmoinformatica.com | E2: % Reserva de Contingencia | G2: ='Presupuesto Detallado Alto'!I2 -> 0.079734219
B3: Líder del Proyecto: Lucas Olea | E3: Presupuesto | F3: Reservas | G3: Total
B4: Fecha de Inicio: 18/08/2026 | D4: Total | E4: =G7+G28 -> 30100000 | F4: =E4*G2 -> 2400000 | G4: =SUM(E4:F4) -> 32500000
B6: Categoría | C6: Recurso | E6: Tipo de Unidades | F6: Tasa | G6: Presupuesto
B7: Costos Directos | G7: =G8+G14+G21+G23 -> 27400000
B8: Labor (Personal) | G8: =G9+G10+G11+G12+G13 -> 23400000
C9: Lucas Olea (Product Owner / Desarrollador) | E9: =VLOOKUP(C9,Datos!$B$8:$E$21,3,) -> Meses | F9: =VLOOKUP(C9,Datos!$B$8:$G$29,6,FALSE()) -> 850000 | G9: =SUMIFS('Presupuesto Detallado Alto'!$I$7:$I$40,'Presupuesto Detallado Alto'!$D$7:$D$40,$C9) -> 5100000
C10: Rodrigo Soto (Arquitectura y UI-UX) | E10: =VLOOKUP(C10,Datos!$B$8:$E$21,3,) -> Meses | F10: =VLOOKUP(C10,Datos!$B$8:$G$29,6,FALSE()) -> 900000 | G10: =SUMIFS('Presupuesto Detallado Alto'!$I$7:$I$39,'Presupuesto Detallado Alto'!$D$7:$D$39,$C10) -> 5400000
C11: Rodrigo Riquelme (QA Lead) | E11: =VLOOKUP(C11,Datos!$B$8:$E$21,3,) -> Meses | F11: =VLOOKUP(C11,Datos!$B$8:$G$29,6,FALSE()) -> 900000 | G11: =SUMIFS('Presupuesto Detallado Alto'!$I$7:$I$39,'Presupuesto Detallado Alto'!$D$7:$D$39,$C11) -> 5400000
C12: Marco Robles (Scrum Master / Gestión de BD) | E12: =VLOOKUP(C12,Datos!$B$8:$E$21,3,) -> Meses | F12: =VLOOKUP(C12,Datos!$B$8:$G$29,6,FALSE()) -> 800000 | G12: =SUMIFS('Presupuesto Detallado Alto'!$I$7:$I$39,'Presupuesto Detallado Alto'!$D$7:$D$39,$C12) -> 4800000
C13: Mantención y soporte (equipo de desarrollo) | E13: =VLOOKUP(C13,Datos!$B$8:$E$21,3,) -> Meses | F13: =VLOOKUP(C13,Datos!$B$8:$G$29,6,FALSE()) -> 450000 | G13: =SUMIFS('Presupuesto Detallado Alto'!$I$7:$I$39,'Presupuesto Detallado Alto'!$D$7:$D$39,$C13) -> 2700000
B14: Materiales | G14: =G15+G16+G17+G18+G19+G20 -> 2300000
C15: Equipamiento tecnológico | E15: =VLOOKUP(C15,Datos!$B$8:$E$21,3,) -> Cantidad | F15: =VLOOKUP(C15,Datos!$B$8:$G$29,6,FALSE()) -> 700000 | G15: =SUMIFS('Presupuesto Detallado Alto'!$I$7:$I$40,'Presupuesto Detallado Alto'!$D$7:$D$40,$C15) -> 700000
C16: Equipamiento tecnológico complementario | E16: =VLOOKUP(C16,Datos!$B$8:$E$21,3,) -> Cantidad | F16: =VLOOKUP(C16,Datos!$B$8:$G$29,6,FALSE()) -> 200000 | G16: =SUMIFS('Presupuesto Detallado Alto'!$I$7:$I$40,'Presupuesto Detallado Alto'!$D$7:$D$40,$C16) -> 200000
C17: Respaldo y almacenamiento externo | E17: =VLOOKUP(C17,Datos!$B$8:$E$21,3,) -> Cantidad | F17: =VLOOKUP(C17,Datos!$B$8:$G$29,6,FALSE()) -> 200000 | G17: =SUMIFS('Presupuesto Detallado Alto'!$I$7:$I$40,'Presupuesto Detallado Alto'!$D$7:$D$40,$C17) -> 200000
C18: Equipos móviles para pruebas | E18: =VLOOKUP(C18,Datos!$B$8:$E$21,3,) -> Cantidad | F18: =VLOOKUP(C18,Datos!$B$8:$G$29,6,FALSE()) -> 400000 | G18: =SUMIFS('Presupuesto Detallado Alto'!$I$7:$I$40,'Presupuesto Detallado Alto'!$D$7:$D$40,$C18) -> 400000
C19: Dispositivos de prueba móviles | E19: =VLOOKUP(C19,Datos!$B$8:$E$21,3,) -> Cantidad | F19: =VLOOKUP(C19,Datos!$B$8:$G$29,6,FALSE()) -> 400000 | G19: =SUMIFS('Presupuesto Detallado Alto'!$I$7:$I$40,'Presupuesto Detallado Alto'!$D$7:$D$40,$C19) -> 400000
C20: Diseño y recursos gráficos | E20: =VLOOKUP(C20,Datos!$B$8:$E$21,3,) -> Cantidad | F20: =VLOOKUP(C20,Datos!$B$8:$G$29,6,FALSE()) -> 400000 | G20: =SUMIFS('Presupuesto Detallado Alto'!$I$7:$I$40,'Presupuesto Detallado Alto'!$D$7:$D$40,$C20) -> 400000
B21: Licencias | G21: =G22 -> 300000
C22: Licencias y herramientas de desarrollo | E22: =VLOOKUP(C22,Datos!$B$8:$E$21,3,) -> Cantidad | F22: =VLOOKUP(C22,Datos!$B$8:$G$29,6,FALSE()) -> 300000 | G22: =SUMIFS('Presupuesto Detallado Alto'!$I$7:$I$40,'Presupuesto Detallado Alto'!$D$7:$D$40,$C22) -> 300000
B23: Servicios Técnicos | G23: =G24+G25+G26+G27 -> 1400000
C24: Configuración inicial del entorno / Cloud | E24: =VLOOKUP(C24,Datos!$B$8:$G$29,3,FALSE()) -> Cantidad | F24: =VLOOKUP(C24,Datos!$B$8:$G$29,6,FALSE()) -> 200000 | G24: =SUMIFS('Presupuesto Detallado Alto'!$I$7:$I$40,'Presupuesto Detallado Alto'!$D$7:$D$40,$C24) -> 200000
C25: Seguridad y pruebas | E25: =VLOOKUP(C25,Datos!$B$8:$G$29,3,FALSE()) -> Cantidad | F25: =VLOOKUP(C25,Datos!$B$8:$G$29,6,FALSE()) -> 400000 | G25: =SUMIFS('Presupuesto Detallado Alto'!$I$7:$I$40,'Presupuesto Detallado Alto'!$D$7:$D$40,$C25) -> 400000
C26: Cloud y despliegue | E26: =VLOOKUP(C26,Datos!$B$8:$G$29,3,FALSE()) -> Cantidad | F26: =VLOOKUP(C26,Datos!$B$8:$G$29,6,FALSE()) -> 500000 | G26: =SUMIFS('Presupuesto Detallado Alto'!$I$7:$I$40,'Presupuesto Detallado Alto'!$D$7:$D$40,$C26) -> 500000
C27: Implementación final | E27: =VLOOKUP(C27,Datos!$B$8:$G$29,3,FALSE()) -> Cantidad | F27: =VLOOKUP(C27,Datos!$B$8:$G$29,6,FALSE()) -> 300000 | G27: =SUMIFS('Presupuesto Detallado Alto'!$I$7:$I$40,'Presupuesto Detallado Alto'!$D$7:$D$40,$C27) -> 300000
B28: Costos Indirectos | G28: =G29+G30+G31 -> 2700000
C29: Servicios básicos / Internet | E29: =VLOOKUP(C29,Datos!$B$8:$G$29,3,FALSE()) -> Meses | F29: =VLOOKUP(C29,Datos!$B$8:$G$29,6,FALSE()) -> 180000 | G29: =SUMIFS('Presupuesto Detallado Alto'!$I$7:$I$40,'Presupuesto Detallado Alto'!$D$7:$D$40,$C29) -> 1080000
C30: Dominio, correo y servicios digitales | E30: =VLOOKUP(C30,Datos!$B$8:$G$29,3,FALSE()) -> Meses | F30: =VLOOKUP(C30,Datos!$B$8:$G$29,6,FALSE()) -> 70000 | G30: =SUMIFS('Presupuesto Detallado Alto'!$I$7:$I$42,'Presupuesto Detallado Alto'!$D$7:$D$42,$C30) -> 420000
C31: Arriendo / cowork | E31: =VLOOKUP(C31,Datos!$B$8:$G$29,3,FALSE()) -> Meses | F31: =VLOOKUP(C31,Datos!$B$8:$G$29,6,FALSE()) -> 200000 | G31: =SUMIFS('Presupuesto Detallado Alto'!$I$7:$I$42,'Presupuesto Detallado Alto'!$D$7:$D$42,$C31) -> 1200000
B33: Conciliación con el flujo de caja
C34: Concepto | D34: Flujo de caja | E34: Presupuesto | F34: Diferencia
C35: Costos de personal 6 meses | D35: =(F9+F10+F11+F12+F13)*6 -> 23400000 | E35: ='Presupuesto Detallado Alto'!I20+'Presupuesto Detallado Alto'!I35 -> 23400000 | F35: =E35-D35 -> 0
C36: Gastos operacionales | D36: 2700000 | E36: ='Presupuesto Detallado Alto'!I38 -> 2700000 | F36: =E36-D36 -> 0
C37: Costos tecnológicos | D37: 2300000 | E37: ='Presupuesto Detallado Alto'!I15+'Presupuesto Detallado Alto'!I26 -> 2300000 | F37: =E37-D37 -> 0
C38: Inversión inicial | D38: 1700000 | E38: ='Presupuesto Detallado Alto'!I8 -> 1700000 | F38: =E38-D38 -> 0
C39: Margen de seguridad / contingencia | D39: 2400000 | E39: ='Presupuesto Detallado Alto'!H4 -> 2400000 | F39: =E39-D39 -> 0
C40: Costo total estimado | D40: =D35+D36+D37+D38+D39 -> 32500000 | E40: =SUM(E35:E39) -> 32500000 | F40: =SUM(F35:F39) -> 0

Sheet Presupuesto Detallado Alto
B1: Presupuesto de Proyecto Alto | G1: RollerSpA
B2: Elaborado por: pmoinformatica.com | G2: % Reserva de Contingencia | I2: =IF(G4=0,0,'Por Recursos Alto'!D39/G4) -> 0.079734219
B3: Líder del Proyecto: Lucas Olea | G3: Presupuesto | H3: Reservas | I3: Total
B4: Fecha de Inicio: 18/08/2026 | E4: Total | G4: =I7+I19+I34 -> 30100000 | H4: =G4*I2 -> 2400000 | I4: =SUM(G4:H4) -> 32500000
B6: Código | C6: Tarea / Actividad | D6: Elemento | E6: Tipo de Recurso | F6: Tipo de Unidades | G6: Unidades | H6: Tasa | I6: Presupuesto
B7: 1 | C7: Inversión inicial y arranque (Mes 0 - M2) | I7: =I8+I15 -> 2400000
B8: 1.1 | C8: Inversión inicial (Mes 0) | I8: =I9 -> 1700000
B9: 1.1.1 | C9: Equipamiento y configuración inicial | H9: =VLOOKUP(D10,Datos!$B$8:$E$21,4,) | I9: =SUM(I10:I14) -> 1700000
D10: Equipamiento tecnológico | E10: =VLOOKUP(D10,Datos!$B$8:$E$21,2,) -> Materiales | F10: =VLOOKUP(D10,Datos!$B$8:$E$21,3,) -> Cantidad | G10: 1 | H10: =VLOOKUP(D10,Datos!$B$8:$G$29,6,FALSE()) -> 700000 | I10: =H10*G10 -> 700000
D11: Equipos móviles para pruebas | E11: =VLOOKUP(D11,Datos!$B$8:$E$21,2,) -> Materiales | F11: =VLOOKUP(D11,Datos!$B$8:$E$21,3,) -> Cantidad | G11: 1 | H11: =VLOOKUP(D11,Datos!$B$8:$G$29,6,FALSE()) -> 400000 | I11: =H11*G11 -> 400000
D12: Respaldo y almacenamiento externo | E12: =VLOOKUP(D12,Datos!$B$8:$G$29,2,FALSE()) -> Materiales | F12: =VLOOKUP(D12,Datos!$B$8:$G$29,3,FALSE()) -> Cantidad | G12: 1 | H12: =VLOOKUP(D12,Datos!$B$8:$G$29,6,FALSE()) -> 200000 | I12: =H12*G12 -> 200000
D13: Configuración inicial del entorno / Cloud | E13: =VLOOKUP(D13,Datos!$B$8:$G$29,2,FALSE()) -> Servicios Técnicos | F13: =VLOOKUP(D12,Datos!$B$8:$G$29,3,FALSE()) -> Cantidad | G13: 1 | H13: =VLOOKUP(D13,Datos!$B$8:$G$29,6,FALSE()) -> 200000 | I13: =H13*G13 -> 200000
D14: Equipamiento tecnológico complementario | E14: =VLOOKUP(D14,Datos!$B$8:$G$29,2,FALSE()) -> Materiales | F14: =VLOOKUP(D13,Datos!$B$8:$G$29,3,FALSE()) -> Cantidad | G14: 1 | H14: =VLOOKUP(D14,Datos!$B$8:$G$29,6,FALSE()) -> 200000 | I14: =H14*G14 -> 200000
B15: 46054 | C15: Herramientas y recursos de diseño (M1 - M2) | I15: =I16 -> 700000
B16: 1.2.1 | C16: Licencias, equipamiento complementario y diseño | I16: =I17+I18 -> 700000
D17: Licencias y herramientas de desarrollo | E17: =VLOOKUP(D17,Datos!$B$8:$E$21,2,) -> Licencias | F17: =VLOOKUP(D17,Datos!$B$8:$E$21,3,) -> Cantidad | G17: 1 | H17: =VLOOKUP(D17,Datos!$B$8:$G$29,6,FALSE()) -> 300000 | I17: =G17*H17 -> 300000
D18: Diseño y recursos gráficos | E18: =VLOOKUP(D18,Datos!$B$8:$E$21,2,) -> Materiales | F18: =VLOOKUP(D18,Datos!$B$8:$E$21,3,) -> Cantidad | G18: 1 | H18: =VLOOKUP(D18,Datos!$B$8:$G$29,6,FALSE()) -> 400000 | I18: =G18*H18 -> 400000
B19: 2 | C19: Desarrollo, pruebas y entrega (M1 - M6) | I19: =I20+I26 -> 22300000
B20: 2.1 | C20: Desarrollo del sistema | I20: =I21 -> 20700000
B21: 2.1.1 | C21: Equipo de desarrollo (M1-M6) | I21: =SUM(I22:I25) -> 20700000
D22: Lucas Olea (Product Owner / Desarrollador) | E22: =VLOOKUP(D22,Datos!$B$8:$E$21,2,) -> Labor (Personal) | F22: =VLOOKUP(D22,Datos!$B$8:$E$21,3,) -> Meses | G22: 6 | H22: =VLOOKUP(D22,Datos!$B$8:$G$29,6,FALSE()) -> 850000 | I22: =G22*H22 -> 5100000
D23: Rodrigo Soto (Arquitectura y UI-UX) | E23: =VLOOKUP(D23,Datos!$B$8:$E$21,2,) -> Labor (Personal) | F23: =VLOOKUP(D23,Datos!$B$8:$E$21,3,) -> Meses | G23: 6 | H23: =VLOOKUP(D23,Datos!$B$8:$G$29,6,FALSE()) -> 900000 | I23: =G23*H23 -> 5400000
D24: Rodrigo Riquelme (QA Lead) | E24: =VLOOKUP(D24,Datos!$B$8:$E$21,2,) -> Labor (Personal) | F24: =VLOOKUP(D24,Datos!$B$8:$E$21,3,) -> Meses | G24: 6 | H24: =VLOOKUP(D24,Datos!$B$8:$G$29,6,FALSE()) -> 900000 | I24: =G24*H24 -> 5400000
D25: Marco Robles (Scrum Master / Gestión de BD) | E25: =VLOOKUP(D25,Datos!$B$8:$E$21,2,) -> Labor (Personal) | F25: =VLOOKUP(D25,Datos!$B$8:$E$21,3,) -> Meses | G25: 6 | H25: =VLOOKUP(D25,Datos!$B$8:$G$29,6,FALSE()) -> 800000 | I25: =G25*H25 -> 4800000
B26: 46055 | C26: Pruebas, despliegue y entrega | I26: =I27+I30+I32 -> 1600000
B27: 2.2.1 | C27: Pruebas y QA (M2-M3) | I27: =I28+I29 -> 800000
D28: Dispositivos de prueba móviles | E28: =VLOOKUP(D28,Datos!$B$8:$E$21,2,) -> Materiales | F28: =VLOOKUP(D28,Datos!$B$8:$E$21,3,) -> Cantidad | G28: 1 | H28: =VLOOKUP(D28,Datos!$B$8:$G$29,6,FALSE()) -> 400000 | I28: =G28*H28 -> 400000
D29: Seguridad y pruebas | E29: =VLOOKUP(D29,Datos!$B$8:$G$29,2,FALSE()) -> Servicios Técnicos | F29: =VLOOKUP(D29,Datos!$B$8:$G$29,3,FALSE()) -> Cantidad | G29: 1 | H29: =VLOOKUP(D29,Datos!$B$8:$G$29,6,FALSE()) -> 400000 | I29: =H29*G29 -> 400000
B30: 2.2.2 | C30: Cloud y despliegue (M5) | I30: =I31 -> 500000
D31: Cloud y despliegue | E31: =VLOOKUP(D31,Datos!$B$8:$G$29,2,FALSE()) -> Servicios Técnicos | F31: =VLOOKUP(D31,Datos!$B$8:$G$29,3,FALSE()) -> Cantidad | G31: 1 | H31: =VLOOKUP(D31,Datos!$B$8:$G$29,6,FALSE()) -> 500000 | I31: =G31*H31 -> 500000
B32: 2.2.3 | C32: Documentación y entrega (M6) | I32: =I33 -> 300000
D33: Implementación final | E33: =VLOOKUP(D33,Datos!$B$8:$G$29,2,FALSE()) -> Servicios Técnicos | F33: =VLOOKUP(D33,Datos!$B$8:$G$29,3,FALSE()) -> Cantidad | G33: 1 | H33: =VLOOKUP(D33,Datos!$B$8:$G$29,6,FALSE()) -> 300000 | I33: =G33*H33 -> 300000
B34: 3 | C34: Desarrollo, pruebas y entrega (M1 - M6) | I34: =I35+I38 -> 5400000
B35: 46025 | C35: Soporte y mantención | I35: =I36 -> 2700000
B36: 3.1.1 | C36: Mantención y soporte (M1-M6) | I36: =SUM(I37) -> 2700000
D37: Mantención y soporte (equipo de desarrollo) | E37: =VLOOKUP(D37,Datos!$B$8:$E$21,2,) -> Labor (Personal) | F37: =VLOOKUP(D37,Datos!$B$8:$E$21,3,) -> Meses | G37: 6 | H37: =VLOOKUP(D37,Datos!$B$8:$G$29,6,FALSE()) -> 450000 | I37: =G37*H37 -> 2700000
B38: 46056 | C38: Gastos operacionales | I38: =I39 -> 2700000
B39: 3.2.1 | C39: Servicios y gastos generales (M1 - M6) | I39: =+I40+I41+I42 -> 2700000
D40: Servicios básicos / Internet | E40: =VLOOKUP(D40,Datos!$B$8:$G$29,2,FALSE()) -> Gastos Indirectos | F40: =VLOOKUP(D40,Datos!$B$8:$G$29,3,FALSE()) -> Meses | G40: 6 | H40: =VLOOKUP(D40,Datos!$B$8:$G$29,6,FALSE()) -> 180000 | I40: =H40*G40 -> 1080000
D41: Dominio, correo y servicios digitales | E41: =VLOOKUP(D41,Datos!$B$8:$G$29,2,FALSE()) -> Gastos Indirectos | F41: =VLOOKUP(D41,Datos!$B$8:$G$29,3,FALSE()) -> Meses | G41: 6 | H41: =VLOOKUP(D41,Datos!$B$8:$G$29,6,FALSE()) -> 70000 | I41: =H41*G41 -> 420000
...

Sheet Datos
B1: Presupuesto de Proyecto | D1: RollerSpA
B2: Elaborado por: pmoinformatica.com
B3: Líder del Proyecto: Lucas Olea
B4: Fecha de Inicio: 18/08/2026
B6: Elemento | C6: Tipo de Recurso | D6: Tipo de Unidades | E6: Tasa Baja | F6: Tasa Media | G6: Tasa Alta
B8: Lucas Olea (Product Owner / Desarrollador) | C8: Labor (Personal) | D8: Meses | E8: 600000 | F8: 700000 | G8: 850000
B9: Rodrigo Soto (Arquitectura y UI-UX) | C9: Labor (Personal) | D9: Meses | E9: 600000 | F9: 750000 | G9: 900000
B10: Rodrigo Riquelme (QA Lead) | C10: Labor (Personal) | D10: Meses | E10: 600000 | F10: 750000 | G10: 900000
B11: Marco Robles (Scrum Master / Gestión de BD) | C11: Labor (Personal) | D11: Meses | E11: 500000 | F11: 650000 | G11: 800000
B12: Mantención y soporte (equipo de desarrollo) | C12: Labor (Personal) | D12: Meses | E12: 300000 | F12: 350000 | G12: 450000
B13: Equipamiento tecnológico | C13: Materiales | D13: Cantidad | F13: 500000 | G13: 700000
B14: Equipamiento tecnológico complementario | C14: Materiales | D14: Cantidad | E14: 500000 | G14: 200000
B15: Periféricos y accesorios | C15: Materiales | D15: Cantidad | E15: 250000 | F15: 200000
B16: Respaldo y almacenamiento externo | C16: Materiales | D16: Cantidad | E16: 150000 | F16: 150000 | G16: 200000
B17: Equipos móviles para pruebas | C17: Materiales | D17: Cantidad | G17: 400000
B18: Dispositivos de prueba móviles | C18: Materiales | D18: Cantidad | E18: 250000 | F18: 300000 | G18: 400000
B19: Diseño y recursos gráficos | C19: Materiales | D19: Cantidad | E19: 150000 | F19: 200000 | G19: 400000
B20: Materiales QA | C20: Materiales | D20: Cantidad | F20: 250000
B21: Licencias y herramientas de desarrollo | C21: Licencias | D21: Cantidad | E21: 150000 | F21: 200000 | G21: 300000
B22: Configuración inicial del entorno / Cloud | C22: Servicios Técnicos | D22: Cantidad | E22: 100000 | F22: 150000 | G22: 200000
B23: Seguridad y pruebas | C23: Servicios Técnicos | D23: Cantidad | G23: 400000
B24: Cloud y despliegue | C24: Servicios Técnicos | D24: Cantidad | E24: 200000 | F24: 300000 | G24: 500000
B25: Documentación y entrega | C25: Servicios Técnicos | D25: Cantidad | E25: 100000 | F25: 150000
B26: Implementación final | C26: Servicios Técnicos | D26: Cantidad | G26: 300000
B27: Servicios básicos / Internet | C27: Gastos Indirectos | D27: Meses | E27: 100000 | F27: 120000 | G27: 180000
B28: Dominio, correo y servicios digitales | C28: Gastos Indirectos | D28: Meses | E28: 30000 | F28: 50000 | G28: 70000
B29: Arriendo / cowork | C29: Gastos Indirectos | D29: Meses | G29: 200000

Sheet Instructivo
B1: Presupuesto de Proyecto
B2: Elaborado por: pmoinformatica.com
B4: Hoja: Tasas
B5: Descripción: | C5: Se usa para registrar los datos maestros para el cálculo del Presupuesto a partir de los recursos.
B6: Columna | C6: Instrucciones
B8: Elemento | C8: Aquí se especifica el nombre del Recurso, por ejemplo Analista de Sistemas 1, Electricista 1, Gerente de Proyectos, etc.
B9: Tipo de Recurso | C9: Indica si es un Recurso de tipo Labor, cuando es una persona, Consultor, para servicios especializados contratados a terceros, Materiales (por ej. Componentes Electronicos, Piezas, entre otros.), Licencias de Propiedad Intelectual, Gastos por viajes, Gastos indirectos, o cualquier otro que sea necesario especificar.
B10: Tipo de Unidades | C10: El tipo de unidad para medir la utilización del recurso, para el caso de personas, pueden ser las horas o jornadas, para materiales, la cantidad de piezas, volumenes o peso. Pueden utilizarse otras según sea el caso.
B11: Tasa | C11: La tasa en moneda a aplicar por la utilización del recurso, por ejemplo para personas esto será el costo por hora o jornada, para consultores la tarifa, para materiales el costo unitario, y así sucesivamente según el tipo de recurso.
B13: Hoja: Presupuesto detallado
B14: Descripción: | C14: Se detallan los costos por recurso para cada actividad del Proyecto. Luego estos se sumarizan por actividades de mayor nivel
B15: Columna | C15: Instrucciones
B17: Código | C17: Código de Paquete de Trabajo, Tarea de Proyecto o Subtarea, según el método de desglose y codificación de las tareas seleccionado.
B18: Tarea / Actividad | C18: Nombre de la tarea para la cual se está especificando el Presupuesto. Aquí se puede presentar el desglose en tres niveles y la plantilla esta prefabricada para permitir la totalización.
B19: Elemento | C19: Aquí se especifica el nombre del Recurso, por ejemplo Analista de Sistemas 1, Electricista 1, Gerente de Proyectos, etc. Es importante que todo Recurso asignado en esta hoja, corresponda con uno registrado en la hoja de "Datos", para que así el libro Excel pueda determinar la tasa automáticamente.
B20: Tipo de Recurso | C20: Indica si es un Recurso de tipo Labor, Materiales, Licencias, Gastos por viajes, Gastos indirectos, o cualquier otro. Su valor lo obtiene el libro Excel automáticamente, buscando en la Hoja "Datos" la Tasa que corresponde al Elemento especificado.
B21: Tipo de Unidades | C21: El tipo de unidad para medir la utilización del recurso, su valor lo obtiene el libro Excel automáticamente, buscando en la Hoja "Datos" la Tasa que corresponde al Elemento especificado.
B22: Unidades | C22: Aquí se registra el número de unidades del Recurso que consumirá la actividad, debe ser especificado según la estimación realizada (según método de estimación seleccionado).
B23: Tasa | C23: La tasa en moneda a aplicar por la utilización del recurso, su valor lo obtiene el libro Excel automáticamente, buscando en la Hoja "Datos" la Tasa que corresponde al Elemento especificado.
B24: Presupuesto | C24: Multiplicando la tasa en moneda por el uso del recurso, por las unidades, se obtiene el costo total para la actividad por el uso de dicho recurso.
B26: Hoja: Presupuesto por Recursos
B27: Descripción: | C27: En esta hoja se totaliza el presupuesto asociado a cada Recurso. Para ello, se sumariza el presupuesto de cada recurso en cada actividad.
B28: Columna | C28: Instrucciones
B30: Categoría | C30: Se usa esta columna para categorízar los Recursos, como por ejemplo "Costos Directos" y "Costos Indirectos".
B31: Recurso | C31: Aquí se especifica el nombre del Recurso, por ejemplo Analista de Sistemas 1, Electricista 1, Gerente de Proyectos, etc. Es importante que todo Recurso asignado en esta hoja, corresponda con uno registrado en la hoja de "Datos", para que así el libro Excel pueda determinar la tasa automáticamente.
B32: Tipo de Unidades | C32: El tipo de unidad para medir la utilización del recurso, su valor lo obtiene el libro Excel automáticamente, buscando en la Hoja "Datos" la Tasa que corresponde al Elemento especificado.
B33: Tasa | C33: La tasa en moneda a aplicar por la utilización del recurso, su valor lo obtiene el libro Excel automáticamente, buscando en la Hoja "Datos" la Tasa que corresponde al Elemento especificado.
B34: Presupuesto | C34: En esta columna se sumariza el Presupuesto del Recurso en cada actividad de la hoja de Presupuesto Detallado, presentando de esta forma un subtotal por Recurso.
